<?xml version="1.0"?>
<sdf version="1.10">
  <model name="inspection_robot">
    <pose>0 0 0.01 0 0 0</pose>
    <link name="base_footprint"/>
    <link name="base_link">
      <pose relative_to="base_footprint">0 0 0.01 0 0 0</pose>
      <inertial>
        <pose>0 0 0.08 0 0 0</pose><mass>1.3729096</mass>
        <inertia><ixx>0.02</ixx><iyy>0.02</iyy><izz>0.03</izz><ixy>0</ixy><ixz>0</ixz><iyz>0</iyz></inertia>
      </inertial>
      <collision name="base_collision"><pose>-0.032 0 0.084 0 0 0</pose><geometry><box><size>0.28 0.30 0.16</size></box></geometry></collision>
      <visual name="base_visual">
        <pose>-0.032 0 0.084 0 0 0</pose>
        <geometry><mesh><uri>model://turtlebot3_common/meshes/bases/waffle_pi_base.stl</uri><scale>0.001 0.001 0.001</scale></mesh></geometry>
        <material><diffuse>0.08 0.12 0.16 1</diffuse></material>
      </visual>
    </link>
    <joint name="base_joint" type="fixed"><parent>base_footprint</parent><child>base_link</child></joint>

    <link name="wheel_left_link">
      <pose relative_to="base_link">0 0.144 0.023 1.57079632679 0 0</pose>
      <inertial><mass>0.0285</mass><inertia><ixx>0.00002</ixx><iyy>0.00002</iyy><izz>0.00002</izz><ixy>0</ixy><ixz>0</ixz><iyz>0</iyz></inertia></inertial>
      <collision name="collision"><geometry><cylinder><radius>0.033</radius><length>0.018</length></cylinder></geometry><surface><friction><ode><mu>1.0</mu><mu2>1.0</mu2></ode></friction></surface></collision>
      <visual name="visual"><geometry><mesh><uri>model://turtlebot3_common/meshes/wheels/left_tire.stl</uri><scale>0.001 0.001 0.001</scale></mesh></geometry></visual>
    </link>
    <link name="wheel_right_link">
      <pose relative_to="base_link">0 -0.144 0.023 1.57079632679 0 0</pose>
      <inertial><mass>0.0285</mass><inertia><ixx>0.00002</ixx><iyy>0.00002</iyy><izz>0.00002</izz><ixy>0</ixy><ixz>0</ixz><iyz>0</iyz></inertia></inertial>
      <collision name="collision"><geometry><cylinder><radius>0.033</radius><length>0.018</length></cylinder></geometry><surface><friction><ode><mu>1.0</mu><mu2>1.0</mu2></ode></friction></surface></collision>
      <visual name="visual"><geometry><mesh><uri>model://turtlebot3_common/meshes/wheels/right_tire.stl</uri><scale>0.001 0.001 0.001</scale></mesh></geometry></visual>
    </link>
    <joint name="wheel_left_joint" type="revolute"><parent>base_link</parent><child>wheel_left_link</child><axis><xyz expressed_in="__model__">0 1 0</xyz></axis></joint>
    <joint name="wheel_right_joint" type="revolute"><parent>base_link</parent><child>wheel_right_link</child><axis><xyz expressed_in="__model__">0 1 0</xyz></axis></joint>

    <link name="caster_link">
      <pose relative_to="base_link">-0.177 0 0.005 0 0 0</pose>
      <inertial><mass>0.005</mass><inertia><ixx>0.00001</ixx><iyy>0.00001</iyy><izz>0.00001</izz><ixy>0</ixy><ixz>0</ixz><iyz>0</iyz></inertia></inertial>
      <collision name="collision"><geometry><sphere><radius>0.012</radius></sphere></geometry><surface><friction><ode><mu>0.01</mu><mu2>0.01</mu2></ode></friction></surface></collision>
    </link>
    <joint name="caster_joint" type="ball"><parent>base_link</parent><child>caster_link</child></joint>

    <link name="laser_frame">
      <pose relative_to="base_link">-0.064 0 0.20 0 0 0</pose>
      <inertial><mass>0.114</mass><inertia><ixx>0.001</ixx><iyy>0.001</iyy><izz>0.001</izz><ixy>0</ixy><ixz>0</ixz><iyz>0</iyz></inertia></inertial>
      <visual name="visual"><geometry><mesh><uri>model://turtlebot3_common/meshes/sensors/lds.stl</uri><scale>0.001 0.001 0.001</scale></mesh></geometry></visual>
      <sensor name="planar_lidar" type="gpu_lidar">
        <always_on>true</always_on><visualize>false</visualize><update_rate>10</update_rate>
        <topic>scan</topic><gz_frame_id>laser_frame</gz_frame_id>
        <ray><scan><horizontal><samples>360</samples><resolution>1.0</resolution><min_angle>0.0</min_angle><max_angle>6.28318530718</max_angle></horizontal></scan><range><min>0.12</min><max>10.0</max><resolution>0.01</resolution></range><noise><type>gaussian</type><mean>0.0</mean><stddev>0.01</stddev></noise></ray>
      </sensor>
    </link>
    <joint name="laser_joint" type="fixed"><parent>base_link</parent><child>laser_frame</child></joint>

    <link name="camera_link"><pose relative_to="base_link">0.073 -0.011 0.094 0 0 0</pose></link>
    <joint name="camera_joint" type="fixed"><parent>base_link</parent><child>camera_link</child></joint>
    <link name="camera_optical_frame">
      <pose relative_to="camera_link">0 0 0 -1.57079632679 0 -1.57079632679</pose>
      <inertial><mass>0.035</mass><inertia><ixx>0.001</ixx><iyy>0.001</iyy><izz>0.001</izz><ixy>0</ixy><ixz>0</ixz><iyz>0</iyz></inertia></inertial>
      <sensor name="rgb_camera" type="camera">
        <pose>0 0 0 0 -1.57079632679 0</pose>
        <always_on>true</always_on><visualize>false</visualize><update_rate>15</update_rate>
        <topic>camera/image_raw</topic><gz_frame_id>camera_optical_frame</gz_frame_id>
        <camera><camera_info_topic>camera/camera_info</camera_info_topic><horizontal_fov>1.085595</horizontal_fov><image><width>640</width><height>480</height><format>R8G8B8</format></image><clip><near>0.03</near><far>50</far></clip><noise><type>gaussian</type><mean>0.0</mean><stddev>0.007</stddev></noise></camera>
      </sensor>
    </link>
    <joint name="camera_optical_joint" type="fixed"><parent>camera_link</parent><child>camera_optical_frame</child></joint>

    <plugin filename="gz-sim-diff-drive-system" name="gz::sim::systems::DiffDrive">
      <left_joint>wheel_left_joint</left_joint><right_joint>wheel_right_joint</right_joint>
      <wheel_separation>0.287</wheel_separation><wheel_radius>0.033</wheel_radius>
      <max_linear_acceleration>1.0</max_linear_acceleration><topic>cmd_vel</topic>
      <odom_topic>odom</odom_topic><frame_id>odom</frame_id><child_frame_id>base_footprint</child_frame_id>
      <odom_publisher_frequency>30</odom_publisher_frequency><tf_topic>tf</tf_topic>
    </plugin>
    <plugin filename="gz-sim-joint-state-publisher-system" name="gz::sim::systems::JointStatePublisher">
      <topic>joint_states</topic><joint_name>wheel_left_joint</joint_name><joint_name>wheel_right_joint</joint_name>
    </plugin>
  </model>
</sdf>
